01/23/2025 18:57:07 - INFO - __main__ - ***** Running training *****
01/23/2025 18:57:07 - INFO - __main__ -   Num examples = 90092
01/23/2025 18:57:07 - INFO - __main__ -   Num batches each epoch = 704
01/23/2025 18:57:07 - INFO - __main__ -   Num Epochs = 114
01/23/2025 18:57:07 - INFO - __main__ -   Instantaneous batch size per device = 64
01/23/2025 18:57:07 - INFO - __main__ -   Total train batch size (w. parallel, distributed & accumulation) = 128
01/23/2025 18:57:07 - INFO - __main__ -   Gradient Accumulation steps = 1
01/23/2025 18:57:07 - INFO - __main__ -   Total optimization steps = 80000
01/23/2025 18:57:07 - INFO - __main__ -  do_classifier_free_guidance = True
01/23/2025 18:57:07 - INFO - __main__ -  conditioning_dropout_prob = 0.05
Checkpoint 'latest' does not exist. Starting a new training run.
Steps:   0%|                                                                                                                                                           | 1/80000 [00:09<211:20:11,  9.51s/it]01/23/2025 18:57:18 - INFO - __main__ - Running unseen_object_with_random_light_condition validation...
cc_projection/diffusion_pytorch_model.safetensors not found
The config attributes {'cc_projection': ['pipeline_zero1to3', 'CCProjection']} were passed to Neural_Gaffer_StableDiffusionPipeline, but are not expected and will be ignored. Please verify your model_index.json configuration file.
Keyword arguments {'cc_projection': ['pipeline_zero1to3', 'CCProjection']} are not expected by Neural_Gaffer_StableDiffusionPipeline and will be ignored.
0it [00:02, ?it/s]
Traceback (most recent call last):
  File "/share/phoenix/nfs02/S6/localdisk/hj453/code/Neural_Gaffer/neural_gaffer_training.py", line 1267, in <module>
    main(args)
  File "/share/phoenix/nfs02/S6/localdisk/hj453/code/Neural_Gaffer/neural_gaffer_training.py", line 1107, in main
    image_logs, temp_log = log_validation(
  File "/share/phoenix/nfs02/S6/localdisk/hj453/code/Neural_Gaffer/neural_gaffer_training.py", line 135, in log_validation
    prediction_image_sample1_list.append(np.array(cur_predicted_images[1][i]))
IndexError: list index out of range
[rank0]: Traceback (most recent call last):
[rank0]:   File "/share/phoenix/nfs02/S6/localdisk/hj453/code/Neural_Gaffer/neural_gaffer_training.py", line 1267, in <module>
[rank0]:     main(args)
[rank0]:   File "/share/phoenix/nfs02/S6/localdisk/hj453/code/Neural_Gaffer/neural_gaffer_training.py", line 1107, in main
[rank0]:     image_logs, temp_log = log_validation(
[rank0]:   File "/share/phoenix/nfs02/S6/localdisk/hj453/code/Neural_Gaffer/neural_gaffer_training.py", line 135, in log_validation
[rank0]:     prediction_image_sample1_list.append(np.array(cur_predicted_images[1][i]))
[rank0]: IndexError: list index out of range
